Workbook
Name 新建文本文档: INDEX!$G$6:$H$21

Sheet INDEX
D1: rdim | E1: cdim
A2: par | B2: KOULX | C2: =B2&"!"&"J6" -> KOULX!J6 | D2: 1 | E2: 2
A3: par | B3: GUWUX | C3: =B3&"!"&"J6" -> GUWUX!J6 | D3: 1 | E3: 2
A4: par | B4: LISHX | C4: =B4&"!"&"J6" -> LISHX!J6 | D4: 1 | E4: 2
A5: par | B5: ENGYX | C5: =B5&"!"&"J6" -> ENGYX!J6 | D5: 1 | E5: 2
A6: par | B6: RICEX | C6: =B6&"!"&"J6" -> RICEX!J6 | D6: 1 | E6: 2
A7: par | B7: WHEAX | C7: =B7&"!"&"J6" -> WHEAX!J6 | D7: 1 | E7: 2
A8: par | B8: MAIZX | C8: =B8&"!"&"J6" -> MAIZX!J6 | D8: 1 | E8: 2
A9: par | B9: BARLX | C9: =B9&"!"&"J6" -> BARLX!J6 | D9: 1 | E9: 2
A10: par | B10: SOYSX | C10: =B10&"!"&"J6" -> SOYSX!J6 | D10: 1 | E10: 2
A11: par | B11: SOYOX | C11: =B11&"!"&"J6" -> SOYOX!J6 | D11: 1 | E11: 2
A12: par | B12: SOYMX | C12: =B12&"!"&"J6" -> SOYMX!J6 | D12: 1 | E12: 2
A13: par | B13: RAPSX | C13: =B13&"!"&"J6" -> RAPSX!J6 | D13: 1 | E13: 2
... A60: par | B60: CRSHX | C60: =B60&"!"&"J6" -> CRSHX!J6 | D60: 1 | E60: 2

Sheet 结果整理
M6: 变化率 | N6: 情景1 | O6: 情景2 | P6: 情景3 | Q6: 情景4 | R6: 情景5 | V6: 变化量 | W6: 情景1 | X6: 情景2 | Y6: 情景3 | Z6: 情景4 | AA6: 情景5
B7: 人均消费量 | C7: 畜禽肉

Sheet 结果
B4: 粮食
C5: =LISHX!K6 -> BASE | D5: =LISHX!L6 -> BASE | E5: =LISHX!M6 -> BASE | F5: =LISHX!N6 -> BASE | G5: =LISHX!O6 -> BASE | H5: =LISHX!P6 -> BASE | I5: =LISHX!Q6 -> BASE | J5: =LISHX!R6 -> BASE | ... T5: =LISHX!AB6 -> 0
C6: =LISHX!K7 -> 2024 | D6: =LISHX!L7 -> 2025 | E6: =LISHX!M7 -> 2026 | F6: =LISHX!N7 -> 2027 | G6: =LISHX!O7 -> 2028 | H6: =LISHX!P7 -> 2029 | I6: =LISHX!Q7 -> 2030 | J6: =LISHX!R7 -> 2031 | ... T6: =LISHX!AB7 -> 0
B7: =LISHX!J8 -> AREA | C7: =LISHX!K8 -> 11931.9 | D7: =LISHX!L8 -> 11940.9 | E7: =LISHX!M8 -> 11953.292 | F7: =LISHX!N8 -> 11966.122 | G7: =LISHX!O8 -> 11979.567 | H7: =LISHX!P8 -> 11993.244 | I7: =LISHX!Q8 -> 12007.471 | ... T7: =LISHX!AB8 -> 0
B8: =LISHX!J9 -> YIELD | C8: =LISHX!K9 -> 33.889185 | D8: =LISHX!L9 -> 34.307583 | E8: =LISHX!M9 -> 34.461505 | F8: =LISHX!N9 -> 34.618846 | G8: =LISHX!O9 -> 34.780358 | H8: =LISHX!P9 -> 34.946599 | I8: =LISHX!Q9 -> 35.117623 | ... T8: =LISHX!AB9 -> 0
B9: =LISHX!J10 -> TOTAL SUPPLY | C9: =LISHX!K10 -> 86177 | D9: =LISHX!L10 -> 85215.3 | E9: =LISHX!M10 -> 85177.637 | F9: =LISHX!N10 -> 85488.842 | G9: =LISHX!O10 -> 85633.991 | H9: =LISHX!P10 -> 85796.771 | I9: =LISHX!Q10 -> 85971.271 | ... T9: =LISHX!AB10 -> 0
B10: =LISHX!J11 -> PRODUCTION | C10: =LISHX!K11 -> 70650 | D10: =LISHX!L11 -> 71488 | E10: =LISHX!M11 -> 71845.738 | F10: =LISHX!N11 -> 72211.87 | G10: =LISHX!O11 -> 72589.79 | H10: =LISHX!P11 -> 72976.885 | I10: =LISHX!Q11 -> 73376.606 | ... T10: =LISHX!AB11 -> 0
B11: =LISHX!J12 -> NET IMPORT | C11: =LISHX!K12 -> 15527 | D11: =LISHX!L12 -> 13727.3 | E11: =LISHX!M12 -> 13331.899 | F11: =LISHX!N12 -> 13276.972 | G11: =LISHX!O12 -> 13044.201 | H11: =LISHX!P12 -> 12819.886 | I11: =LISHX!Q12 -> 12594.665 | ... T11: =LISHX!AB12 -> 0
B12: =LISHX!J13 -> TOTAL DEMAND | C12: =LISHX!K13 -> 86177 | D12: =LISHX!L13 -> 85215.3 | E12: =LISHX!M13 -> 85177.637 | F12: =LISHX!N13 -> 85488.842 | G12: =LISHX!O13 -> 85633.991 | H12: =LISHX!P13 -> 85796.771 | I12: =LISHX!Q13 -> 85971.271 | ... T12: =LISHX!AB13 -> 0
B13: =LISHX!J14 -> PER CAPITA FOOD DEMAND | C13: =LISHX!K14 -> 207.12395 | D13: =LISHX!L14 -> 203.45097 | E13: =LISHX!M14 -> 202.00714 | F13: =LISHX!N14 -> 200.65554 | G13: =LISHX!O14 -> 199.40306 | H13: =LISHX!P14 -> 198.25002 | I13: =LISHX!Q14 -> 197.18117 | ... T13: =LISHX!AB14 -> 0
B14: =LISHX!J15 -> SEED DEMAND | C14: =LISHX!K15 -> 1118.0902 | D14: =LISHX!L15 -> 1138.4333 | E14: =LISHX!M15 -> 1139.2731 | F14: =LISHX!N15 -> 1140.1761 | G14: =LISHX!O15 -> 1141.1425 | H14: =LISHX!P15 -> 1142.1748 | I14: =LISHX!Q15 -> 1143.3076 | ... T14: =LISHX!AB15 -> 0
B15: =LISHX!J16 -> FEED DEMAND | C15: =LISHX!K16 -> 23305.064 | D15: =LISHX!L16 -> 26188.313 | E15: =LISHX!M16 -> 26225.434 | F15: =LISHX!N16 -> 26223.937 | G15: =LISHX!O16 -> 26256.313 | H15: =LISHX!P16 -> 26303.924 | I15: =LISHX!Q16 -> 26351.731 | ... T15: =LISHX!AB16 -> 0
B16: =LISHX!J17 -> PROCESSING DEMAND | C16: =LISHX!K17 -> 12831.67 | D16: =LISHX!L17 -> 12317.699 | E16: =LISHX!M17 -> 12581.525 | F16: =LISHX!N17 -> 12853.773 | G16: =LISHX!O17 -> 13128.923 | H16: =LISHX!P17 -> 13408.24 | I16: =LISHX!Q17 -> 13695.423 | ... T16: =LISHX!AB17 -> 0
B17: =LISHX!J18 -> CRUSH DEMAND | C17: =LISHX!K18 -> 10240 | D17: =LISHX!L18 -> 10650 | E17: =LISHX!M18 -> 10423.108 | F17: =LISHX!N18 -> 10418.995 | G17: =LISHX!O18 -> 10447.838 | H17: =LISHX!P18 -> 10492.532 | I17: =LISHX!Q18 -> 10537.434 | ... T17: =LISHX!AB18 -> 0
B18: =LISHX!J19 -> WASTE DEMAND | C18: =LISHX!K19 -> 3251.4002 | D18: =LISHX!L19 -> 3184.7093 | E18: =LISHX!M19 -> 3203.1732 | F18: =LISHX!N19 -> 3222.1174 | G18: =LISHX!O19 -> 3241.7154 | H18: =LISHX!P19 -> 3261.848 | I18: =LISHX!Q19 -> 3282.6856 | ... T18: =LISHX!AB19 -> 0
B19: =LISHX!J20 -> OTHER DEMAND | C19: =LISHX!K20 -> 0.747113 | D19: =LISHX!L20 -> 1.835365 | E19: =LISHX!M20 -> 1.8359945 | F19: =LISHX!N20 -> 1.8366582 | G19: =LISHX!O20 -> 1.8373813 | H19: =LISHX!P20 -> 1.8382277 | I19: =LISHX!Q20 -> 1.8391448 | ... T19: =LISHX!AB20 -> 0
B23: 水稻
B24: =RICEX!J6 -> 0 | C24: =RICEX!K6 -> BASE | D24: =RICEX!L6 -> BASE | E24: =RICEX!M6 -> BASE | F24: =RICEX!N6 -> BASE | G24: =RICEX!O6 -> BASE | H24: =RICEX!P6 -> BASE | I24: =RICEX!Q6 -> BASE | ... T24: =RICEX!AB6 -> 0
B25: =RICEX!J7 -> 0 | C25: =RICEX!K7 -> 2024 | D25: =RICEX!L7 -> 2025 | E25: =RICEX!M7 -> 2026 | F25: =RICEX!N7 -> 2027 | G25: =RICEX!O7 -> 2028 | H25: =RICEX!P7 -> 2029 | I25: =RICEX!Q7 -> 2030 | ... T25: =RICEX!AB7 -> 0
B26: =RICEX!J8 -> AREA | C26: =RICEX!K8 -> 2900.69 | D26: =RICEX!L8 -> 2901.22 | E26: =RICEX!M8 -> 2899.6812 | F26: =RICEX!N8 -> 2898.2505 | G26: =RICEX!O8 -> 2896.8979 | H26: =RICEX!P8 -> 2895.4794 | I26: =RICEX!Q8 -> 2894.0518 | ... T26: =RICEX!AB8 -> 0
B27: =RICEX!J9 -> YIELD | C27: =RICEX!K9 -> 7154.677 | D27: =RICEX!L9 -> 7205.2792 | E27: =RICEX!M9 -> 7229.9166 | F27: =RICEX!N9 -> 7254.7175 | G27: =RICEX!O9 -> 7279.7223 | H27: =RICEX!P9 -> 7304.8594 | I27: =RICEX!Q9 -> 7330.1534 | ... T27: =RICEX!AB9 -> 0
B28: =RICEX!J10 -> TOTAL SUPPLY | C28: =RICEX!K10 -> 20832.07 | D28: =RICEX!L10 -> 21106.96 | E28: =RICEX!M10 -> 21304.815 | F28: =RICEX!N10 -> 21345.047 | G28: =RICEX!O10 -> 21349.459 | H28: =RICEX!P10 -> 21361.983 | I28: =RICEX!Q10 -> 21382.975 | ... T28: =RICEX!AB10 -> 0
B29: =RICEX!J11 -> PRODUCTION | C29: =RICEX!K11 -> 20753.5 | D29: =RICEX!L11 -> 20904.1 | E29: =RICEX!M11 -> 20964.453 | F29: =RICEX!N11 -> 21025.989 | G29: =RICEX!O11 -> 21088.612 | H29: =RICEX!P11 -> 21151.07 | I29: =RICEX!Q11 -> 21213.844 | ... T29: =RICEX!AB11 -> 0
B30: =RICEX!J12 -> NET IMPORT | C30: =RICEX!K12 -> 78.57 | D30: =RICEX!L12 -> 202.86 | E30: =RICEX!M12 -> 340.3618 | F30: =RICEX!N12 -> 319.05859 | G30: =RICEX!O12 -> 260.84719 | H30: =RICEX!P12 -> 210.91325 | I30: =RICEX!Q12 -> 169.13118 | ... T30: =RICEX!AB12 -> 0
B31: =RICEX!J13 -> TOTAL DEMAND | C31: =RICEX!K13 -> 20832.07 | D31: =RICEX!L13 -> 21106.96 | E31: =RICEX!M13 -> 21304.815 | F31: =RICEX!N13 -> 21345.047 | G31: =RICEX!O13 -> 21349.459 | H31: =RICEX!P13 -> 21361.983 | I31: =RICEX!Q13 -> 21382.975 | ... T31: =RICEX!AB13 -> 0
B32: =RICEX!J14 -> PER CAPITA FOOD DEMAND | C32: =RICEX!K14 -> 111.12847 | D32: =RICEX!L14 -> 110.68482 | E32: =RICEX!M14 -> 109.77017 | F32: =RICEX!N14 -> 108.90481 | G32: =RICEX!O14 -> 108.0971 | H32: =RICEX!P14 -> 107.35248 | I32: =RICEX!Q14 -> 106.66086 | ... T32: =RICEX!AB14 -> 0
B33: =RICEX!J15 -> SEED DEMAND | C33: =RICEX!K15 -> 141 | D33: =RICEX!L15 -> 142 | E33: =RICEX!M15 -> 141.92468 | F33: =RICEX!N15 -> 141.85466 | G33: =RICEX!O15 -> 141.78846 | H33: =RICEX!P15 -> 141.71903 | I33: =RICEX!Q15 -> 141.64916 | ... T33: =RICEX!AB15 -> 0
B34: =RICEX!J16 -> FEED DEMAND | C34: =RICEX!K16 -> 1069.86 | D34: =RICEX!L16 -> 863.84 | E34: =RICEX!M16 -> 860.54282 | F34: =RICEX!N16 -> 858.98196 | G34: =RICEX!O16 -> 857.41669 | H34: =RICEX!P16 -> 855.64637 | I34: =RICEX!Q16 -> 853.74897 | ... T34: =RICEX!AB16 -> 0
B35: =RICEX!J17 -> PROCESSING DEMAND | C35: =RICEX!K17 -> 1780 | D35: =RICEX!L17 -> 1800 | E35: =RICEX!M17 -> 1907.7131 | F35: =RICEX!N17 -> 2021.3924 | G35: =RICEX!O17 -> 2140.1374 | H35: =RICEX!P17 -> 2264.3502 | I35: =RICEX!Q17 -> 2394.9644 | ... T35: =RICEX!AB17 -> 0
... B43: =RICEX!J25 -> 0 | C43: =RICEX!K25 -> 0 | D43: =RICEX!L25 -> 0 | E43: =RICEX!M25 -> 0 | F43: =RICEX!N25 -> 0 | G43: =RICEX!O25 -> 0 | H43: =RICEX!P25 -> 0 | I43: =RICEX!Q25 -> 0 | ... T43: =RICEX!AB25 -> 0
B44: =RICEX!J26 -> 0 | C44: =RICEX!#REF! -> #REF! | D44: =RICEX!#REF! -> #REF! | E44: =RICEX!#REF! -> #REF! | F44: =RICEX!#REF! -> #REF! | G44: =RICEX!#REF! -> #REF! | H44: =RICEX!#REF! -> #REF! | I44: =RICEX!#REF! -> #REF! | J44: =RICEX!#REF! -> #REF! | ... T44: =RICEX!#REF! -> #REF!
B45: =RICEX!J27 -> 0 | C45: =RICEX!#REF! -> #REF! | D45: =RICEX!#REF! -> #REF! | E45: =RICEX!#REF! -> #REF! | F45: =RICEX!#REF! -> #REF! | G45: =RICEX!#REF! -> #REF! | H45: =RICEX!#REF! -> #REF! | I45: =RICEX!#REF! -> #REF! | J45: =RICEX!#REF! -> #REF! | ... T45: =RICEX!#REF! -> #REF!
B46: =RICEX!J28 -> 0 | C46: =RICEX!#REF! -> #REF! | D46: =RICEX!#REF! -> #REF! | E46: =RICEX!#REF! -> #REF! | F46: =RICEX!#REF! -> #REF! | G46: =RICEX!#REF! -> #REF! | H46: =RICEX!#REF! -> #REF! | I46: =RICEX!#REF! -> #REF! | J46: =RICEX!#REF! -> #REF! | ... T46: =RICEX!#REF! -> #REF!
B47: =RICEX!J29 -> 0 | C47: =RICEX!K26 -> 0 | D47: =RICEX!L26 -> 0 | E47: =RICEX!M26 -> 0 | F47: =RICEX!N26 -> 0 | G47: =RICEX!O26 -> 0 | H47: =RICEX!P26 -> 0 | I47: =RICEX!Q26 -> 0 | J47: =RICEX!R26 -> 0 | ... T47: =RICEX!AB26 -> 0
B48: =RICEX!J30 -> 0 | C48: =RICEX!K27 -> 0 | D48: =RICEX!L27 -> 0 | E48: =RICEX!M27 -> 0 | F48: =RICEX!N27 -> 0 | G48: =RICEX!O27 -> 0 | H48: =RICEX!P27 -> 0 | I48: =RICEX!Q27 -> 0 | J48: =RICEX!R27 -> 0 | ... T48: =RICEX!AB27 -> 0
B49: =RICEX!J31 -> 0 | C49: =RICEX!K28 -> 0 | D49: =RICEX!L28 -> 0 | E49: =RICEX!M28 -> 0 | F49: =RICEX!N28 -> 0 | G49: =RICEX!O28 -> 0 | H49: =RICEX!P28 -> 0 | I49: =RICEX!Q28 -> 0 | J49: =RICEX!R28 -> 0 | ... T49: =RICEX!AB28 -> 0
B50: =RICEX!J32 -> 0 | C50: =RICEX!K29 -> 0 | D50: =RICEX!L29 -> 0 | E50: =RICEX!M29 -> 0 | F50: =RICEX!N29 -> 0 | G50: =RICEX!O29 -> 0 | H50: =RICEX!P29 -> 0 | I50: =RICEX!Q29 -> 0 | J50: =RICEX!R29 -> 0 | ... T50: =RICEX!AB29 -> 0
B51: =RICEX!J33 -> 0 | C51: =RICEX!K30 -> 0 | D51: =RICEX!L30 -> 0 | E51: =RICEX!M30 -> 0 | F51: =RICEX!N30 -> 0 | G51: =RICEX!O30 -> 0 | H51: =RICEX!P30 -> 0 | I51: =RICEX!Q30 -> 0 | J51: =RICEX!R30 -> 0 | ... T51: =RICEX!AB30 -> 0
B52: =RICEX!J34 -> 0 | C52: =RICEX!K31 -> 0 | D52: =RICEX!L31 -> 0 | E52: =RICEX!M31 -> 0 | F52: =RICEX!N31 -> 0 | G52: =RICEX!O31 -> 0 | H52: =RICEX!P31 -> 0 | I52: =RICEX!Q31 -> 0 | J52: =RICEX!R31 -> 0 | ... T52: =RICEX!AB31 -> 0
B53: =RICEX!J35 -> 0 | C53: =RICEX!K32 -> 0 | D53: =RICEX!L32 -> 0 | E53: =RICEX!M32 -> 0 | F53: =RICEX!N32 -> 0 | G53: =RICEX!O32 -> 0 | H53: =RICEX!P32 -> 0 | I53: =RICEX!Q32 -> 0 | J53: =RICEX!R32 -> 0 | ... T53: =RICEX!AB32 -> 0
...

Sheet KOULX
B6: BASE | K6: BASE | L6: BASE | M6: BASE | N6: BASE | O6: BASE | P6: BASE | Q6: BASE | R6: BASE | S6: BASE | T6: BASE | U6: BASE | V6: BASE
B7: 2016-2035 | K7: 2024 | L7: 2025 | M7: 2026 | N7: 2027 | O7: 2028 | P7: 2029 | Q7: 2030 | R7: 2031 | S7: 2032 | T7: 2033 | U7: 2034 | V7: 2035
A8: 稻谷种植面积（万公顷） | B8: =(AD8/K8)^(1/19)*100-100 -> -100 | J8: AREA | K8: 5259.43 | L8: 5259.4 | M8: 5256.1127 | N8: 5253.0292 | O8: 5250.1038 | P8: 5247.2418 | Q8: 5244.6107 | R8: 5242.1119 | S8: 5239.7386 | T8: 5237.4845 | U8: 5235.3436 | V8: 5233.3101
A9: 稻谷单产（千克/公顷） | B9: =(AD9/K9)^(1/19)*100-100 -> -100 | J9: YIELD | K9: 13.094246 | L9: 13.145114 | M9: 13.181822 | N9: 13.218894 | O9: 13.256492 | P9: 13.294802 | Q9: 13.333935 | R9: 13.373608 | S9: 13.413911 | T9: 13.454996 | U9: 13.496917 | V9: 13.539758
A10: 总供给 | B10: =(AD10/K10)^(1/19)*100-100 -> -100 | J10: TOTAL SUPPLY | K10: 35948.23 | L10: 35498.88 | M10: 35659.061 | N10: 35669.446 | O10: 35651.151 | P10: 35646.349 | Q10: 35654.094 | R10: 35672.643 | S10: 35713.116 | T10: 35765.111 | U10: 35828.222 | V10: 35903.298
A11: 稻谷产量（万吨） | B11: =(AD11/K11)^(1/19)*100-100 -> -100 | J11: PRODUCTION | K11: 34763.4 | L11: 34911.3 | M11: 34989.709 | N11: 35070.304 | O11: 35153.181 | P11: 35237.992 | Q11: 35326.087 | R11: 35416.334 | S11: 35508.922 | T11: 35604.188 | U11: 35702.229 | V11: 35803.219
A12: 稻谷净进口 | B12: =(AD12/K12)^(1/19)*100-100 -> -100 | J12: NET IMPORT | K12: 1184.83 | L12: 587.58 | M12: 669.35115 | N12: 599.14156 | O12: 497.97017 | P12: 408.35761 | Q12: 328.00683 | R12: 256.30881 | S12: 204.19362 | T12: 160.92251 | U12: 125.99233 | V12: 100.07882
A13: 稻谷总需求（万吨） | B13: =(AD13/K13)^(1/19)*100-100 -> -100 | J13: TOTAL DEMAND | K13: 35948.23 | L13: 35498.88 | M13: 35659.061 | N13: 35669.446 | O13: 35651.151 | P13: 35646.349 | Q13: 35654.094 | R13: 35672.643 | S13: 35713.116 | T13: 35765.111 | U13: 35828.222 | V13: 35903.298
A14: 稻谷人均消费量（千克/人） | B14: =(AD14/K14)^(1/19)*100-100 -> -100 | J14: PER CAPITA FOOD DEMAND | K14: 175.7463 | L14: 173.67908 | M14: 172.21604 | N14: 170.8324 | O14: 169.54156 | P14: 168.34453 | Q14: 167.22564 | R14: 166.17991 | S14: 165.18737 | T14: 164.25145 | U14: 163.36674 | V14: 162.53016
A15: 农村居民在家人均稻谷消费量（千克/人） | B15: =(AD15/K15)^(1/19)*100-100 -> -100 | J15: SEED DEMAND | K15: 791 | L15: 842 | M15: 841.40565 | N15: 840.84503 | O15: 840.31194 | P15: 839.81402 | Q15: 839.38691 | R15: 838.98123 | S15: 838.59589 | T15: 838.22988 | U15: 837.88221 | V15: 837.55198
A16: 农村居民在外人均稻谷消费量（千克/人） | B16: =(AD16/K16)^(1/19)*100-100 -> -100 | J16: FEED DEMAND | K16: 2509.86 | L16: 2903.84 | M16: 2889.8384 | N16: 2882.0942 | O16: 2877.6089 | P16: 2874.4276 | Q16: 2871.1268 | R16: 2867.8254 | S16: 2864.722 | T16: 2861.801 | U16: 2859.0557 | V16: 2856.4772
A17: 城镇居民在家人均稻谷消费量（千克/人） | B17: =(AD17/K17)^(1/19)*100-100 -> -100 | J17: PROCESSING DEMAND | K17: 2930 | L17: 2800 | M17: 2965.3056 | N17: 3139.6647 | O17: 3321.7646 | P17: 3512.1632 | Q17: 3712.2361 | R17: 3920.773 | S17: 4138.5656 | T17: 4366.5107 | U17: 4604.4662 | V17: 4852.6999
A18: 城镇居民在外人均稻谷消费量（千克/人） | B18: =(AD18/K18)^(1/19)*100-100 -> -100 | J18: WASTE DEMAND | K18: 1390.14 | L18: 1396.164 | M18: 1399.3 | N18: 1402.5234 | O18: 1405.8381 | P18: 1409.23 | Q18: 1412.7533 | R18: 1416.3627 | S18: 1420.0656 | T18: 1423.8756 | U18: 1427.7967 | V18: 1431.8356
A19: 农村居民稻谷口粮总消费量（万吨） | B19: =(AD19/K19)^(1/19)*100-100 -> -100 | J19: STOCK CHANGE | K19: 3577.23 | L19: 3156.876 | M19: 3394.4638 | N19: 3467.1849 | O19: 3497.8845 | P19: 3529.1082 | Q19: 3560.9892 | R19: 3593.4468 | S19: 3626.5061 | T19: 3660.207 | U19: 3694.5666 | V19: 3729.6098
... A23: 稻谷加工消费量（万吨） | B23: =(AD23/K23)^(1/19)*100-100 -> -100 | J23: CARBON EMISSION | K23: 21019.604 | L23: 20847.774 | M23: 20833.222 | N23: 20688.718 | O23: 20517.099 | P23: 20354.412 | Q23: 20200.345 | R23: 20053.544 | S23: 19920.304 | T23: 19794.111 | U23: 19674.51 | V23: 19561.761
A24: 稻谷损耗量（万吨） | B24: =(AD24/K24)^(1/19)*100-100 -> #DIV/0!
A25: 稻谷库存变化(万吨） | B25: =(AD25/K25)^(1/19)*100-100 -> #DIV/0!
A26: 稻谷消费者价格（元/吨） | B26: =(AD26/K26)^(1/19)*100-100 -> #DIV/0!
A27: 稻谷生产者价格（元/吨） | B27: =(AD27/K27)^(1/19)*100-100 -> #DIV/0!
A28: 食物总需求 | B28: =(AD28/K28)^(1/19)*100-100 -> #DIV/0!
A29: 农村居民人均稻谷消费量（千克/人） | B29: =(AD29/K29)^(1/19)*100-100 -> #DIV/0!
A30: 城镇居民人均稻谷消费量（千克/人） | B30: =(AD30/K30)^(1/19)*100-100 -> #DIV/0!
A31: 农村居民在家稻谷口粮总消费量（万吨） | B31: =(AD31/K31)^(1/19)*100-100 -> #DIV/0!
A32: 农村居民在外稻谷口粮总消费量（万吨） | B32: =(AD32/K32)^(1/19)*100-100 -> #DIV/0!
A33: 城镇居民在家稻谷口粮总消费量（万吨） | B33: =(AD33/K33)^(1/19)*100-100 -> #DIV/0!
A34: 城镇居民在外稻谷口粮总消费量（万吨） | B34: =(AD34/K34)^(1/19)*100-100 -> #DIV/0!

Sheet GUWUX
L5: =L11/L10 -> 0.98707038 | Y5: =Y11/Y10 -> #DIV/0!
B6: BASE | K6: BASE | L6: BASE | M6: BASE | N6: BASE | O6: BASE | P6: BASE | Q6: BASE | R6: BASE | S6: BASE | T6: BASE | U6: BASE | V6: BASE
B7: 2016-2035 | K7: 2024 | L7: 2025 | M7: 2026 | N7: 2027 | O7: 2028 | P7: 2029 | Q7: 2030 | R7: 2031 | S7: 2032 | T7: 2033 | U7: 2034 | V7: 2035
A8: 稻谷种植面积（万公顷） | B8: =(AD8/K8)^(1/19)*100-100 -> -100 | J8: AREA | K8: 9733.53 | L8: 9752.733 | M8: 9746.3835 | N8: 9740.0332 | O8: 9733.8565 | P8: 9727.4154 | Q8: 9721.1322 | R8: 9715.1657 | S8: 9709.5 | T8: 9704.1197 | U8: 9699.0103 | V8: 9694.1582
A9: 稻谷单产（千克/公顷） | B9: =(AD9/K9)^(1/19)*100-100 -> -100 | J9: YIELD | K9: 19.685963 | L9: 19.849158 | M9: 19.925121 | N9: 20.001675 | O9: 20.07929 | P9: 20.158027 | Q9: 20.23809 | R9: 20.319253 | S9: 20.401694 | T9: 20.485708 | U9: 20.571405 | V9: 20.658953
A10: 总供给 | B10: =(AD10/K10)^(1/19)*100-100 -> -100 | J10: TOTAL SUPPLY | K10: 66803.23 | L10: 65886.69 | M10: 66204.347 | N10: 66603.285 | O10: 66766.124 | P10: 66907.721 | Q10: 67046.616 | R10: 67186.598 | S10: 67344.917 | T10: 67512.373 | U10: 67688.238 | V10: 67873.55
A11: 稻谷产量（万吨） | B11: =(AD11/K11)^(1/19)*100-100 -> -100 | J11: PRODUCTION | K11: 64255.4 | L11: 65034.8 | M11: 65268.951 | N11: 65504.672 | O11: 65744.922 | P11: 65986.43 | Q11: 66232.684 | R11: 66484.579 | S11: 66742.647 | T11: 67007.814 | U11: 67280.385 | V11: 67560.865
A12: 稻谷净进口 | B12: =(AD12/K12)^(1/19)*100-100 -> -100 | J12: NET IMPORT | K12: 2547.83 | L12: 851.89 | M12: 935.39631 | N12: 1098.6134 | O12: 1021.2016 | P12: 921.29058 | Q12: 813.93145 | R12: 702.01893 | S12: 602.27046 | T12: 504.55932 | U12: 407.85276 | V12: 312.68481
A13: 稻谷总需求（万吨） | B13: =(AD13/K13)^(1/19)*100-100 -> -100 | J13: TOTAL DEMAND | K13: 66803.23 | L13: 65886.69 | M13: 66204.347 | N13: 66603.285 | O13: 66766.124 | P13: 66907.721 | Q13: 67046.616 | R13: 67186.598 | S13: 67344.917 | T13: 67512.373 | U13: 67688.238 | V13: 67873.55
A14: 稻谷人均消费量（千克/人） | B14: =(AD14/K14)^(1/19)*100-100 -> -100 | J14: PER CAPITA FOOD DEMAND | K14: 189.16693 | L14: 187.34563 | M14: 185.83736 | N14: 184.41504 | O14: 183.09063 | P14: 181.86537 | Q14: 180.72275 | R14: 179.65659 | S14: 178.64681 | T14: 177.69634 | U14: 176.79949 | V14: 175.95289
A15: 农村居民在家人均稻谷消费量（千克/人） | B15: =(AD15/K15)^(1/19)*100-100 -> -100 | J15: SEED DEMAND | K15: 918 | L15: 966.5 | M15: 965.8208 | N15: 965.16966 | O15: 964.54649 | P15: 963.9494 | Q15: 963.4211 | R15: 962.91934 | S15: 962.44278 | T15: 961.99014 | U15: 961.56023 | V15: 961.1519
A16: 农村居民在外人均稻谷消费量（千克/人） | B16: =(AD16/K16)^(1/19)*100-100 -> -100 | J16: FEED DEMAND | K16: 19709.86 | L16: 22403.84 | M16: 22433.657 | N16: 22432.398 | O16: 22460.043 | P16: 22500.617 | Q16: 22541.307 | R16: 22582.92 | S16: 22626.611 | T16: 22672.27 | U16: 22719.853 | V16: 22769.301
A17: 城镇居民在家人均稻谷消费量（千克/人） | B17: =(AD17/K17)^(1/19)*100-100 -> -100 | J17: PROCESSING DEMAND | K17: 10680 | L17: 10700 | M17: 10954.27 | N17: 11217.059 | O17: 11483.019 | P17: 11753.416 | Q17: 12031.81 | R17: 12313.744 | S17: 12601.076 | T17: 12895.681 | U17: 13196.512 | V17: 13503.731
A18: 城镇居民在外人均稻谷消费量（千克/人） | B18: =(AD18/K18)^(1/19)*100-100 -> -100 | J18: WASTE DEMAND | K18: 2864.74 | L18: 2902.339 | M18: 2913.2621 | N18: 2924.2418 | O18: 2935.4251 | P18: 2946.652 | Q18: 2958.0832 | R18: 2969.7749 | S18: 2981.7518 | T18: 2994.0569 | U18: 3006.7044 | V18: 3019.7179
A19: 农村居民稻谷口粮总消费量（万吨） | B19: =(AD19/K19)^(1/19)*100-100 -> -100 | J19: STOCK CHANGE | K19: 5990.63 | L19: 2594.011 | M19: 2856.9775 | N19: 3224.0769 | O19: 3320.7198 | P19: 3375.5209 | Q19: 3417.2254 | R19: 3453.8988 | S19: 3488.6261 | T19: 3522.7683 | U19: 3556.9579 | V19: 3591.5163
... A23: 稻谷加工消费量（万吨） | B23: =(AD23/K23)^(1/19)*100-100 -> -100 | J23: CARBON EMISSION | K23: 26558.956 | L23: 26182.271 | M23: 26145.339 | N23: 26022.083 | O23: 25831.767 | P23: 25643.697 | Q23: 25461.263 | R23: 25284.169 | S23: 25119.809 | T23: 24961.81 | U23: 24809.648 | V23: 24663.589
A24: 稻谷损耗量（万吨） | B24: =(AD24/K24)^(1/19)*100-100 -> #DIV/0!
A25: 稻谷库存变化(万吨） | B25: =(AD25/K25)^(1/19)*100-100 -> #DIV/0!
A26: 稻谷消费者价格（元/吨） | B26: =(AD26/K26)^(1/19)*100-100 -> #DIV/0!
A27: 稻谷生产者价格（元/吨） | B27: =(AD27/K27)^(1/19)*100-100 -> #DIV/0!
A28: 食物总需求 | B28: =(AD28/K28)^(1/19)*100-100 -> #DIV/0!
A29: 农村居民人均稻谷消费量（千克/人） | B29: =(AD29/K29)^(1/19)*100-100 -> #DIV/0!
A30: 城镇居民人均稻谷消费量（千克/人） | B30: =(AD30/K30)^(1/19)*100-100 -> #DIV/0!
A31: 农村居民在家稻谷口粮总消费量（万吨） | B31: =(AD31/K31)^(1/19)*100-100 -> #DIV/0!
A32: 农村居民在外稻谷口粮总消费量（万吨） | B32: =(AD32/K32)^(1/19)*100-100 -> #DIV/0!
A33: 城镇居民在家稻谷口粮总消费量（万吨） | B33: =(AD33/K33)^(1/19)*100-100 -> #DIV/0!
A34: 城镇居民在外稻谷口粮总消费量（万吨） | B34: =(AD34/K34)^(1/19)*100-100 -> #DIV/0!

Sheet LISHX
X1: =X2/X3 -> -1
X2: =X11-X3 -> -66949.2
X3: 66949.2
K4: 141.67237 | M4: =M16/M10 -> 0.30789107 | V4: =V11/V10 -> 0.86457259 | W4: =W11/W10 -> #DIV/0! | X4: =X11/X13 -> #DIV/0! | AA4: =AA10/AA9 -> #DIV/0!
Y5: =Y11/Y13 -> #DIV/0!
B6: BASE | K6: BASE | L6: BASE | M6: BASE | N6: BASE | O6: BASE | P6: BASE | Q6: BASE | R6: BASE | S6: BASE | T6: BASE | U6: BASE | V6: BASE
B7: 2016-2035 | I7: 1 | K7: 2024 | L7: 2025 | M7: 2026 | N7: 2027 | O7: 2028 | P7: 2029 | Q7: 2030 | R7: 2031 | S7: 2032 | T7: 2033 | U7: 2034 | V7: 2035
A8: 稻谷种植面积（万公顷） | B8: =(AD8/K8)^(1/19)*100-100 -> -100 | I8: 2 | J8: AREA | K8: 11931.9 | L8: 11940.9 | M8: 11953.292 | N8: 11966.122 | O8: 11979.567 | P8: 11993.244 | Q8: 12007.471 | R8: 12022.411 | S8: 12038.056 | T8: 12054.4 | U8: 12071.435 | V8: 12089.157
A9: 稻谷单产（千克/公顷） | B9: =(AD9/K9)^(1/19)*100-100 -> -100 | I9: 3 | J9: YIELD | K9: 33.889185 | L9: 34.307583 | M9: 34.461505 | N9: 34.618846 | O9: 34.780358 | P9: 34.946599 | Q9: 35.117623 | R9: 35.2441 | S9: 35.372479 | T9: 35.503317 | U9: 35.636849 | V9: 35.773408
A10: 总供给 | B10: =(AD10/K10)^(1/19)*100-100 -> -100 | I10: 4 | J10: TOTAL SUPPLY | K10: 86177 | L10: 85215.3 | M10: 85177.637 | N10: 85488.842 | O10: 85633.991 | P10: 85796.771 | Q10: 85971.271 | R10: 86149.017 | S10: 86355.624 | T10: 86578.029 | U10: 86813.898 | V10: 87063.207
A11: 稻谷产量（万吨） | B11: =(AD11/K11)^(1/19)*100-100 -> -100 | I11: 5 | J11: PRODUCTION | K11: 70650 | L11: 71488 | M11: 71845.738 | N11: 72211.87 | O11: 72589.79 | P11: 72976.885 | Q11: 73376.606 | R11: 73734.422 | S11: 74102.016 | T11: 74480.528 | U11: 74870.441 | V11: 75272.462
A12: 稻谷净进口 | B12: =(AD12/K12)^(1/19)*100-100 -> -100 | I12: 6 | J12: NET IMPORT | K12: 15527 | L12: 13727.3 | M12: 13331.899 | N12: 13276.972 | O12: 13044.201 | P12: 12819.886 | Q12: 12594.665 | R12: 12414.594 | S12: 12253.607 | T12: 12097.501 | U12: 11943.457 | V12: 11790.744
A13: 稻谷总需求（万吨） | B13: =(AD13/K13)^(1/19)*100-100 -> -100 | I13: 7 | J13: TOTAL DEMAND | K13: 86177 | L13: 85215.3 | M13: 85177.637 | N13: 85488.842 | O13: 85633.991 | P13: 85796.771 | Q13: 85971.271 | R13: 86149.017 | S13: 86355.624 | T13: 86578.029 | U13: 86813.898 | V13: 87063.207
A14: 稻谷人均消费量（千克/人） | B14: =(AD14/K14)^(1/19)*100-100 -> -100 | I14: 8 | J14: PER CAPITA FOOD DEMAND | K14: 207.12395 | L14: 203.45097 | M14: 202.00714 | N14: 200.65554 | O14: 199.40306 | P14: 198.25002 | Q14: 197.18117 | R14: 196.18836 | S14: 195.25517 | T14: 194.38207 | U14: 193.563 | V14: 192.79424
A15: 农村居民在家人均稻谷消费量（千克/人） | B15: =(AD15/K15)^(1/19)*100-100 -> -100 | I15: 9 | J15: SEED DEMAND | K15: 1118.0902 | L15: 1138.4333 | M15: 1139.2731 | N15: 1140.1761 | O15: 1141.1425 | P15: 1142.1748 | Q15: 1143.3076 | R15: 1144.4992 | S15: 1145.7489 | T15: 1147.056 | U15: 1148.4201 | V15: 1149.8407
A16: 农村居民在外人均稻谷消费量（千克/人） | B16: =(AD16/K16)^(1/19)*100-100 -> -100 | I16: 10 | J16: FEED DEMAND | K16: 23305.064 | L16: 26188.313 | M16: 26225.434 | N16: 26223.937 | O16: 26256.313 | P16: 26303.924 | Q16: 26351.731 | R16: 26400.667 | S16: 26452.039 | T16: 26505.718 | U16: 26561.654 | V16: 26619.774
A17: 城镇居民在家人均稻谷消费量（千克/人） | B17: =(AD17/K17)^(1/19)*100-100 -> -100 | I17: 11 | J17: PROCESSING DEMAND | K17: 12831.67 | L17: 12317.699 | M17: 12581.525 | N17: 12853.773 | O17: 13128.923 | P17: 13408.24 | Q17: 13695.423 | R17: 13985.948 | S17: 14281.783 | T17: 14584.758 | U17: 14893.785 | V17: 15209.019
A18: 城镇居民在外人均稻谷消费量（千克/人） | B18: =(AD18/K18)^(1/19)*100-100 -> -100 | I18: 12 | J18: CRUSH DEMAND | K18: 10240 | L18: 10650 | M18: 10423.108 | N18: 10418.995 | O18: 10447.838 | P18: 10492.532 | Q18: 10537.434 | R18: 10582.903 | S18: 10629.463 | T18: 10677.067 | U18: 10725.696 | V18: 10775.326
A19: 农村居民稻谷口粮总消费量（万吨） | B19: =(AD19/K19)^(1/19)*100-100 -> -100 | I19: 13 | J19: WASTE DEMAND | K19: 3251.4002 | L19: 3184.7093 | M19: 3203.1732 | N19: 3222.1174 | O19: 3241.7154 | P19: 3261.848 | Q19: 3282.6856 | R19: 3300.7635 | S19: 3319.3539 | T19: 3338.5141 | U19: 3358.27 | V19: 3378.6584
A20: 城镇居民稻谷口粮总消费量（万吨） | B20: =(AD20/K20)^(1/19)*100-100 -> -100 | I20: 14 | J20: OTHER DEMAND | K20: 0.747113 | L20: 1.835365 | M20: 1.8359945 | N20: 1.8366582 | O20: 1.8373813 | P20: 1.8382277 | Q20: 1.8391448 | R20: 1.8399169 | S20: 1.8405763 | T20: 1.8411688 | U20: 1.8417163 | V20: 1.8422471
A21: 稻谷种子消费量（万吨） | B21: =(AD21/K21)^(1/19)*100-100 -> -100 | J21: STOCK CHANGE | K21: 6261.1762 | L21: 3151.6856 | M21: 3253.6667 | N21: 3512.0387 | O21: 3532.8127 | P21: 3533.2289 | Q21: 3535.059 | R21: 3537.4805 | S21: 3546.1356 | T21: 3560.1418 | U21: 3578.5989 | V21: 3600.7591
A22: 稻谷饲料消费量（万吨） | B22: =(AD22/K22)^(1/19)*100-100 -> -100 | J22: DOMESTIC DEMAND | K22: 79915.824 | L22: 82063.614 | M22: 81923.97 | N22: 81976.804 | O22: 82101.178 | P22: 82263.543 | Q22: 82436.212 | R22: 82611.536 | S22: 82809.488 | T22: 83017.887 | U22: 83235.299 | V22: 83462.448
A23: 稻谷加工消费量（万吨） | B23: =(AD23/K23)^(1/19)*100-100 -> -100 | J23: energy | K23: 1473.5228 | L23: 1448.9096 | M23: 1439.3555 | N23: 1430.4548 | O23: 1422.2333 | P23: 1414.6897 | Q23: 1407.7248 | R23: 1401.2739 | S23: 1395.2407 | T23: 1389.6185 | U23: 1384.3647 | V23: 1379.4527
J24: TOTAL FOOD DEMAND BY ALL HOUSEHOLD | K24: 29168.852 | L24: 28582.624 | M24: 28349.621 | N24: 28115.968 | O24: 27883.409 | P24: 27652.985 | Q24: 27423.791 | R24: 27194.916 | S24: 26979.26 | T24: 26762.934 | U24: 26545.632 | V24: 26327.987
A25: 稻谷损耗量（万吨） | B25: =(AD25/K25)^(1/19)*100-100 -> -100 | J25: CARBON EMISSION | K25: 27120.777 | L25: 26863.591 | M25: 26727.974 | N25: 26563.987 | O25: 26346.965 | P25: 26139.796 | Q25: 25941.372 | R25: 25758.411 | S25: 25589.816 | T25: 25428.567 | U25: 25273.841 | V25: 25125.699
A26: 稻谷库存变化(万吨） | B26: =(AD26/K26)^(1/19)*100-100 -> #DIV/0!
A27: 稻谷消费者价格（元/吨） | B27: =(AD27/K27)^(1/19)*100-100 -> #DIV/0!
A28: 稻谷生产者价格（元/吨） | B28: =(AD28/K28)^(1/19)*100-100 -> #DIV/0!
A29: 食物总需求 | B29: =(AD29/K29)^(1/19)*100-100 -> #DIV/0!
A30: 农村居民人均稻谷消费量（千克/人） | B30: =(AD30/K30)^(1/19)*100-100 -> #DIV/0!
A31: 城镇居民人均稻谷消费量（千克/人） | B31: =(AD31/K31)^(1/19)*100-100 -> #DIV/0!
A32: 农村居民在家稻谷口粮总消费量（万吨） | B32: =(AD32/K32)^(1/19)*100-100 -> #DIV/0! | I32: 总人口（千人）
A33: 农村居民在外稻谷口粮总消费量（万吨） | B33: =(AD33/K33)^(1/19)*100-100 -> #DIV/0!
A34: 城镇居民在家稻谷口粮总消费量（万吨） | B34: =(AD34/K34)^(1/19)*100-100 -> #DIV/0!
A35: 城镇居民在外稻谷口粮总消费量（万吨） | B35: =(AD35/K35)^(1/19)*100-100 -> #DIV/0!

Sheet PGDPX
I4: 汇率 | J4: 6.4512 | K4: 6.720825 | L4: 7.04225 | M4: 6.7386846 | N4: 6.6114011 | O4: 6.5208986 | P4: 6.5132848 | Q4: 6.4965676 | R4: 6.4798934 | S4: 6.463262 | T4: 6.4466732 | U4: 6.4301271 | V4: 6.4136234 | W4: 6.397162 | X4: 6.3896926 | Y4: 6.3822319 | Z4: 6.37478 | AA4: 6.3673367 | AB4: 6.3599021 | AC4: 6.3524762 | AD4: 6.345059 | AE4: 6.3376504 | AF4: 6.3302505 | AG4: 6.3228593 | AH4: 6.3154766 | AI4: 6.3081026 | AJ4: 6.3007372 | AK4: 6.2933804 | AL4: 6.2860321 | AM4: 6.2786925
K6: BASE | L6: BASE | M6: BASE | N6: BASE | O6: BASE | P6: BASE | Q6: BASE | R6: BASE | S6: BASE | T6: BASE | U6: BASE | V6: BASE
K7: 2024 | L7: 2025 | M7: 2026 | N7: 2027 | O7: 2028 | P7: 2029 | Q7: 2030 | R7: 2031 | S7: 2032 | T7: 2033 | U7: 2034 | V7: 2035
I8: 人均GDP 元 | J8: PER CAPITA GDP | K8: 95796.575 | L8: 99785.677 | M8: 104756.57 | N8: 109998.54 | O8: 115415.18 | P8: 121026.33 | Q8: 126902.63 | R8: 132954.15 | S8: 139128.09 | T8: 145545.65 | U8: 152182.7 | V8: 159036.28
I9: 年度增长率

Sheet CO2EX
K6: BASE | L6: BASE | M6: BASE | N6: BASE | O6: BASE | P6: BASE | Q6: BASE | R6: BASE | S6: BASE | T6: BASE | U6: BASE | V6: BASE
K7: 2024 | L7: 2025 | M7: 2026 | N7: 2027 | O7: 2028 | P7: 2029 | Q7: 2030 | R7: 2031 | S7: 2032 | T7: 2033 | U7: 2034 | V7: 2035
I8: 种植业的排放当量万吨 | J8: CROP EMISSION | K8: 34176.328 | L8: 33530.49 | M8: 33401.666 | N8: 33204.928 | O8: 32954.669 | P8: 32713.053 | Q8: 32478.917 | R8: 32259.01 | S8: 32053.653 | T8: 31854.618 | U8: 31661.033 | V8: 31472.984
I9: 养殖业的排放当量万吨 | J9: LIVESTOCK EMISSION | K9: 31534.668 | L9: 31580.704 | M9: 31018.223 | N9: 30710.926 | O9: 30777.501 | P9: 30987.834 | Q9: 31176.41 | R9: 31347.359 | S9: 31535.823 | T9: 31715.344 | U9: 31884.897 | V9: 32044.485
I10: co2排放当量万吨 | J10: TOTAL EMISSION | K10: 65710.996 | L10: 65111.194 | M10: 64419.889 | N10: 63915.854 | O10: 63732.17 | P10: 63700.886 | Q10: 63655.327 | R10: 63606.369 | S10: 63589.476 | T10: 63569.961 | U10: 63545.93 | V10: 63517.469

Sheet POPUX
K6: BASE | L6: BASE | M6: BASE | N6: BASE | O6: BASE | P6: BASE | Q6: BASE | R6: BASE | S6: BASE | T6: BASE | U6: BASE | V6: BASE
K7: 2024 | L7: 2025 | M7: 2026 | N7: 2027 | O7: 2028 | P7: 2029 | Q7: 2030 | R7: 2031 | S7: 2032 | T7: 2033 | U7: 2034 | V7: 2035
I8: 总人口（千人） | J8: TOTAL POPULATION | K8: 140828 | L8: 140489 | M8: 140339.7 | N8: 140120.57 | O8: 139834.41 | P8: 139485.41 | Q8: 139079.16 | R8: 138616.36 | S8: 138174.37 | T8: 137682.11 | U8: 137142.08 | V8: 136560.03
I9: 城镇人口 | J9: URBAN POPULATION | K9: 94350 | L9: 95380 | M9: 96404.532 | N9: 97265.815 | O9: 97975.818 | P9: 98547.14 | Q9: 98992.235 | R9: 99319.592 | S9: 99591.941 | T9: 99765.558 | U9: 99847.8 | V9: 99848.461
I10: 城镇化率 | J10: URBANIZATION RATE | K10: 0.6699662 | L10: 0.67891436 | M10: 0.686937 | N10: 0.694158 | O10: 0.700656 | P10: 0.706505 | Q10: 0.711769 | R10: 0.716507 | S10: 0.72077 | T10: 0.724608 | U10: 0.728061 | V10: 0.731169

Sheet ENGYX
K6: BASE | L6: BASE | M6: BASE | N6: BASE | O6: BASE | P6: BASE | Q6: BASE | R6: BASE | S6: BASE | T6: BASE | U6: BASE | V6: BASE
K7: 2024 | L7: 2025 | M7: 2026 | N7: 2027 | O7: 2028 | P7: 2029 | Q7: 2030 | R7: 2031 | S7: 2032 | T7: 2033 | U7: 2034 | V7: 2035
H8: 每人每天摄入量 | I8: 膳食能量 | J8: energy | K8: 2960.2672 | L8: 2993.8945 | M8: 2990.0227 | N8: 2987.382 | O8: 2985.9948 | P8: 2985.4468 | Q8: 2985.4638 | R8: 2985.873 | S8: 2986.9847 | T8: 2988.5407 | U8: 2990.4759 | V8: 2992.7348
I9: 蛋白质 | J9: protein | K9: 95.301286 | L9: 96.002425 | M9: 96.007414 | N9: 96.058651 | O9: 96.211691 | P9: 96.40982 | Q9: 96.616761 | R9: 96.830597 | S9: 97.071565 | T9: 97.326039 | U9: 97.5916 | V9: 97.866317
I10: 脂肪 | J10: fat | K10: 115.993 | L10: 119.49443 | M10: 119.86816 | N10: 120.28932 | O10: 120.73679 | P10: 121.19302 | Q10: 121.65348 | R10: 122.10774 | S10: 122.5849 | T10: 123.06616 | U10: 123.54971 | V10: 124.03304
I11: 碳水化合物 | J11: CARBOHYDRATE | K11: 378.22324 | L11: 377.97046 | M11: 376.04784 | N11: 374.26989 | O11: 372.6415 | P11: 371.15658 | Q11: 369.79161 | R11: 368.53187 | S11: 367.36267 | T11: 366.27945 | U11: 365.27307 | V11: 364.33774
H12: 膳食能量构成 | I12: 蛋白质 | J12: ENERGY FROM PROTEIN | K12: 0.1287739 | L12: 0.12826427 | M12: 0.12843703 | N12: 0.12861918 | O12: 0.12888394 | P12: 0.12917305 | Q12: 0.12944958 | R12: 0.12971831 | S12: 0.12999272 | T12: 0.13026564 | U12: 0.13053655 | V12: 0.1308052
I13: 脂肪 | J13: ENERGY FROM FAT | K13: 0.35264958 | L13: 0.35921434 | M13: 0.36080442 | N13: 0.36239217 | O13: 0.36390924 | P13: 0.3653514 | Q13: 0.36673742 | R13: 0.36805641 | S13: 0.36935713 | T13: 0.37061413 | U13: 0.37182959 | V13: 0.37300244
I14: 碳水化合物 | J14: ENERGY FROM CARBOHYDRATE | K14: 0.51857652 | L14: 0.51252139 | M14: 0.51075855 | N14: 0.50898865 | O14: 0.50720682 | P14: 0.50547554 | Q14: 0.50381299 | R14: 0.50222528 | S14: 0.50065015 | T14: 0.49912023 | U14: 0.49763386 | V14: 0.49619236
H15: 膳食能量构成 | I15: 植物类食物 | J15: ENERGY FROM PLANT | K15: 0.61250707 | L15: 0.60222069 | M15: 0.60040893 | N15: 0.59859551 | O15: 0.59675268 | P15: 0.5949603 | Q15: 0.59325034 | R15: 0.59162278 | S15: 0.59001262 | T15: 0.5884531 | U15: 0.58694171 | V15: 0.58547942
I16: 油脂类食物 | J16: ENERGY FROM OIL | K16: 0.18063161 | L16: 0.18480705 | M16: 0.18622095 | N16: 0.18763398 | O16: 0.18897909 | P16: 0.19026939 | Q16: 0.19153504 | R16: 0.19275657 | S16: 0.19395935 | T16: 0.19512992 | U16: 0.19627 | V16: 0.19737881
I17: 动物类食物 | J17: ENERGY FROM ANIMAL | K17: 0.19030998 | L17: 0.19418302 | M17: 0.1944952 | N17: 0.19481822 | O17: 0.19524888 | P17: 0.19569183 | Q17: 0.19608265 | R17: 0.1964398 | S17: 0.19680345 | T17: 0.19715291 | U17: 0.19748841 | V17: 0.19780942
H18: 蛋白质构成 | I18: 植物类食物 | J18: PROTEIN FROM PLANT | K18: 0.59154502 | L18: 0.58147729 | M18: 0.58019928 | N18: 0.57888142 | O18: 0.5771274 | P18: 0.57526933 | Q18: 0.5735194 | R18: 0.5718446 | S18: 0.57015767 | T18: 0.56850415 | U18: 0.56688397 | V18: 0.56529852
I19: 动物类食物 | J19: PROTEIN FROM ANIMAL | K19: 0.40845498 | L19: 0.41852271 | M19: 0.41980072 | N19: 0.42111858 | O19: 0.4228726 | P19: 0.42473067 | Q19: 0.4264806 | R19: 0.4281554 | S19: 0.42984233 | T19: 0.43149585 | U19: 0.43311603 | V19: 0.43470148

Sheet RICEX
K3: =K9/15 -> 476.97847 | L3: =L9/15 -> 480.35194 | M3: =M9/15 -> 481.99444 | N3: =N9/15 -> 483.64783 | O3: =O9/15 -> 485.31482 | P3: =P9/15 -> 486.99063 | Q3: =Q9/15 -> 488.67689 | R3: =R9/15 -> 490.37537 | ... W3: =W9/15 -> 0
L4: =L5/GUWUX!L22 -> 3.762876e-05
L5: =L11/L10 -> 0.99038895
K6: BASE | L6: BASE | M6: BASE | N6: BASE | O6: BASE | P6: BASE | Q6: BASE | R6: BASE | S6: BASE | T6: BASE | U6: BASE | V6: BASE
K7: 2024 | L7: 2025 | M7: 2026 | N7: 2027 | O7: 2028 | P7: 2029 | Q7: 2030 | R7: 2031 | S7: 2032 | T7: 2033 | U7: 2034 | V7: 2035
H8: 种植面积（万公顷） | J8: AREA | K8: 2900.69 | L8: 2901.22 | M8: 2899.6812 | N8: 2898.2505 | O8: 2896.8979 | P8: 2895.4794 | Q8: 2894.0518 | R8: 2892.6961 | S8: 2891.4087 | T8: 2890.186 | U8: 2889.0249 | V8: 2887.9221
H9: 单产（千克/公顷） | J9: YIELD | K9: 7154.677 | L9: 7205.2792 | M9: 7229.9166 | N9: 7254.7175 | O9: 7279.7223 | P9: 7304.8594 | Q9: 7330.1534 | R9: 7355.6305 | S9: 7381.3127 | T9: 7407.2362 | U9: 7433.4142 | V9: 7459.8671
H10: 总供给（万吨） | J10: TOTAL SUPPLY | K10: 20832.07 | L10: 21106.96 | M10: 21304.815 | N10: 21345.047 | O10: 21349.459 | P10: 21361.983 | Q10: 21382.975 | R10: 21410.923 | S10: 21452.91 | T10: 21502.319 | U10: 21558.87 | V10: 21623.098
H11: 产量（万吨） | J11: PRODUCTION | K11: 20753.5 | L11: 20904.1 | M11: 20964.453 | N11: 21025.989 | O11: 21088.612 | P11: 21151.07 | Q11: 21213.844 | R11: 21277.604 | S11: 21342.392 | T11: 21408.291 | U11: 21475.318 | V11: 21543.515
H12: 净进口（万吨） | J12: NET IMPORT | K12: 78.57 | L12: 202.86 | M12: 340.3618 | N12: 319.05859 | O12: 260.84719 | P12: 210.91325 | Q12: 169.13118 | R12: 133.31877 | S12: 110.5182 | T12: 94.028241 | U12: 83.551563 | V12: 79.582612
H13: 总需求（万吨） | J13: TOTAL DEMAND | K13: 20832.07 | L13: 21106.96 | M13: 21304.815 | N13: 21345.047 | O13: 21349.459 | P13: 21361.983 | Q13: 21382.975 | R13: 21410.923 | S13: 21452.91 | T13: 21502.319 | U13: 21558.87 | V13: 21623.098
H14: 人均食用消费量（千克/人） | J14: PER CAPITA FOOD DEMAND | K14: 111.12847 | L14: 110.68482 | M14: 109.77017 | N14: 108.90481 | O14: 108.0971 | P14: 107.35248 | Q14: 106.66086 | R14: 106.01542 | S14: 105.40339 | T14: 104.82685 | U14: 104.28236 | V14: 103.7679
H15: 种子消费量（万吨） | J15: SEED DEMAND | K15: 141 | L15: 142 | M15: 141.92468 | N15: 141.85466 | O15: 141.78846 | P15: 141.71903 | Q15: 141.64916 | R15: 141.5828 | S15: 141.51979 | T15: 141.45994 | U15: 141.40311 | V15: 141.34913
H16: 饲料消费量（万吨） | J16: FEED DEMAND | K16: 1069.86 | L16: 863.84 | M16: 860.54282 | N16: 858.98196 | O16: 857.41669 | P16: 855.64637 | Q16: 853.74897 | R16: 851.778 | S16: 849.84737 | T16: 847.95216 | U16: 846.09008 | V16: 844.25814
H17: 加工消费量（万吨） | J17: PROCESSING DEMAND | K17: 1780 | L17: 1800 | M17: 1907.7131 | N17: 2021.3924 | O17: 2140.1374 | P17: 2264.3502 | Q17: 2394.9644 | R17: 2531.1207 | S17: 2673.3413 | T17: 2822.2363 | U17: 2977.6986 | V17: 3139.9
H18: 损耗和浪费（万吨） | J18: WASTE DEMAND | K18: 830.14 | L18: 836.164 | M18: 838.57813 | N18: 841.03955 | O18: 843.54449 | P18: 846.04281 | Q18: 848.55376 | R18: 851.10416 | S18: 853.69567 | T18: 856.33162 | U18: 859.01274 | V18: 861.7406
H19: 库存变化（万吨） | J19: STOCK CHANGE | K19: 1361.07 | L19: 1914.956 | M19: 2150.9429 | N19: 2221.9741 | O19: 2250.878 | P19: 2280.1198 | Q19: 2309.7558 | R19: 2339.8649 | S19: 2370.4594 | T19: 2401.5565 | U19: 2433.1664 | V19: 2465.302
... H23: 碳排放（万吨） | J23: CARBON EMISSION | K23: 17647.483 | L23: 17664.067 | M23: 17677.811 | N23: 17559.586 | O23: 17412.487 | P23: 17273.137 | Q23: 17141.588 | R23: 17016.394 | S23: 16902.967 | T23: 16795.748 | U23: 16694.346 | V23: 16598.99

Sheet WHEAX
K3: =K9/15 -> 395.9713 | L3: =L9/15 -> 395.989 | M3: =M9/15 -> 396.79366 | N3: =N9/15 -> 397.61176 | O3: =O9/15 -> 398.4513 | P3: =P9/15 -> 399.32951 | Q3: =Q9/15 -> 400.25213 | R3: =R9/15 -> 401.19848 | ... W3: =W9/15 -> 0
L5: =L11/L10 -> 0.97326833
K6: BASE | L6: BASE | M6: BASE | N6: BASE | O6: BASE | P6: BASE | Q6: BASE | R6: BASE | S6: BASE | T6: BASE | U6: BASE | V6: BASE
K7: 2024 | L7: 2025 | M7: 2026 | N7: 2027 | O7: 2028 | P7: 2029 | Q7: 2030 | R7: 2031 | S7: 2032 | T7: 2033 | U7: 2034 | V7: 2035
H8: 种植面积（万公顷） | J8: AREA | K8: 2358.74 | L8: 2358.18 | M8: 2356.4315 | N8: 2354.7787 | O8: 2353.2059 | P8: 2351.7623 | Q8: 2350.5589 | R8: 2349.4157 | S8: 2348.3299 | T8: 2347.2985 | U8: 2346.3187 | V8: 2345.388
H9: 单产（千克/公顷） | J9: YIELD | K9: 5939.5694 | L9: 5939.835 | M9: 5951.9049 | N9: 5964.1764 | O9: 5976.7694 | P9: 5989.9427 | Q9: 6003.7819 | R9: 6017.9772 | S9: 6032.5981 | T9: 6047.7599 | U9: 6063.5032 | V9: 6079.8913
H10: 总供给（万吨） | J10: TOTAL SUPPLY | K10: 15116.16 | L10: 14391.92 | M10: 14354.245 | N10: 14324.399 | O10: 14301.692 | P10: 14284.366 | Q10: 14271.119 | R10: 14261.72 | S10: 14260.206 | T10: 14262.792 | U10: 14269.352 | V10: 14280.201
H11: 产量（万吨） | J11: PRODUCTION | K11: 14009.9 | L11: 14007.2 | M11: 14025.256 | N11: 14044.316 | O11: 14064.569 | P11: 14086.922 | Q11: 14112.243 | R11: 14138.73 | S11: 14166.53 | T11: 14195.897 | U11: 14226.911 | V11: 14259.704
H12: 净进口（万吨） | J12: NET IMPORT | K12: 1106.26 | L12: 384.72 | M12: 328.98935 | N12: 280.08297 | O12: 237.12298 | P12: 197.44436 | Q12: 158.87565 | R12: 122.99004 | S12: 93.675424 | T12: 66.894266 | U12: 42.440769 | V12: 20.496204
H13: 总需求（万吨） | J13: TOTAL DEMAND | K13: 15116.16 | L13: 14391.92 | M13: 14354.245 | N13: 14324.399 | O13: 14301.692 | P13: 14284.366 | Q13: 14271.119 | R13: 14261.72 | S13: 14260.206 | T13: 14262.792 | U13: 14269.352 | V13: 14280.201
H14: 人均食用消费量（千克/人） | J14: PER CAPITA FOOD DEMAND | K14: 64.617832 | L14: 62.994256 | M14: 62.445863 | N14: 61.92759 | O14: 61.444454 | P14: 60.992051 | Q14: 60.564777 | R14: 60.164485 | S14: 59.783983 | T14: 59.424598 | U14: 59.084383 | V14: 58.76226
H15: 种子消费量（万吨） | J15: SEED DEMAND | K15: 650 | L15: 700 | M15: 699.48097 | N15: 698.99037 | O15: 698.52349 | P15: 698.09499 | Q15: 697.73775 | R15: 697.39843 | S15: 697.0761 | T15: 696.76993 | U15: 696.4791 | V15: 696.20285
H16: 食物消费需求（万吨） | J16: FEED DEMAND | K16: 1440 | L16: 2040 | M16: 2029.2955 | N16: 2023.1122 | O16: 2020.1922 | P16: 2018.7812 | Q16: 2017.3779 | R16: 2016.0474 | S16: 2014.8746 | T16: 2013.8488 | U16: 2012.9656 | V16: 2012.2191
H17: 饲料消费量（万吨） | J17: PROCESSING DEMAND | K17: 1150 | L17: 1000 | M17: 1057.5925 | N17: 1118.2723 | O17: 1181.6272 | P17: 1247.813 | Q17: 1317.2717 | R17: 1389.6523 | S17: 1465.2243 | T17: 1544.2744 | U17: 1626.7676 | V17: 1712.7999
H18: 加工消费量（万吨） | J18: WASTE DEMAND | K18: 560 | L18: 560 | M18: 560.72187 | N18: 561.48387 | O18: 562.29358 | P18: 563.18723 | Q18: 564.19956 | R18: 565.25851 | S18: 566.36994 | T18: 567.54402 | U18: 568.78392 | V18: 570.09498
H19: 损耗和浪费（万吨） | J19: STOCK CHANGE | K19: 2216.16 | L19: 1241.92 | M19: 1243.5209 | N19: 1245.2108 | O19: 1247.0065 | P19: 1248.9884 | Q19: 1251.2334 | R19: 1253.5819 | S19: 1256.0467 | T19: 1258.6505 | U19: 1261.4002 | V19: 1264.3078
... H23: 碳排放（万吨） | J23: CARBON EMISSION | K23: 3372.1208 | L23: 3183.7078 | M23: 3155.4113 | N23: 3129.1321 | O23: 3104.6118 | P23: 3081.2751 | Q23: 3058.7569 | R23: 3037.15 | S23: 3017.337 | T23: 2998.3622 | U23: 2980.1638 | V23: 2962.7705

Sheet MAIZX
K3: =K11/15 -> 1966.1333 | L3: =L11/15 -> 2008.2333 | M3: =M11/15 -> 2018.6161 | N3: =N11/15 -> 2028.9578 | O3: =O11/15 -> 2039.4494 | P3: =P11/15 -> 2049.8959 | Q3: =Q11/15 -> 2060.4398 | R3: =R11/15 -> 2071.2163 | ... W3: =W11/15 -> 0
L5: =L11/L10 -> 0.9913021
B6: BASE | K6: BASE | L6: BASE | M6: BASE | N6: BASE | O6: BASE | P6: BASE | Q6: BASE | R6: BASE | S6: BASE | T6: BASE | U6: BASE | V6: BASE
B7: 2016-2035 | K7: 2024 | L7: 2025 | M7: 2026 | N7: 2027 | O7: 2028 | P7: 2029 | Q7: 2030 | R7: 2031 | S7: 2032 | T7: 2033 | U7: 2034 | V7: 2035
A8: 总供给 | B8: =(AD8/K8)^(1/19)*100-100 -> -100 | J8: AREA | K8: 4474.1 | L8: 4493.333 | M8: 4490.2708 | N8: 4487.004 | O8: 4483.7527 | P8: 4480.1736 | Q8: 4476.5214 | R8: 4473.0538 | S8: 4469.7614 | T8: 4466.6352 | U8: 4463.6668 | V8: 4460.848
A9: 玉米产量（万吨） | B9: =(AD9/K9)^(1/19)*100-100 -> -100 | J9: YIELD | K9: 6591.7168 | L9: 6704.0435 | M9: 6743.2995 | N9: 6782.7815 | O9: 6822.7984 | P9: 6863.2248 | Q9: 6904.1549 | R9: 6945.6452 | S9: 6987.7834 | T9: 7030.712 | U9: 7074.4877 | V9: 7119.1947
A10: 玉米种植面积（万公顷） | B10: =(AD10/K10)^(1/19)*100-100 -> -100 | J10: TOTAL SUPPLY | K10: 30855 | L10: 30387.81 | M10: 30545.286 | N10: 30933.839 | O10: 31114.972 | P10: 31261.372 | Q10: 31392.522 | R10: 31513.955 | S10: 31631.802 | T10: 31747.263 | U10: 31860.016 | V10: 31970.252
A11: 玉米单产（千克/公顷） | B11: =(AD11/K11)^(1/19)*100-100 -> -100 | J11: PRODUCTION | K11: 29492 | L11: 30123.5 | M11: 30279.241 | N11: 30434.368 | O11: 30591.741 | P11: 30748.439 | Q11: 30906.597 | R11: 31068.245 | S11: 31233.725 | T11: 31403.626 | U11: 31578.156 | V11: 31757.646
A12: 玉米净进口 | B12: =(AD12/K12)^(1/19)*100-100 -> -100 | J12: NET IMPORT | K12: 1363 | L12: 264.31 | M12: 266.04515 | N12: 499.47185 | O12: 523.23147 | P12: 512.93297 | Q12: 485.92462 | R12: 445.71012 | S12: 398.07684 | T12: 343.63681 | U12: 281.86043 | V12: 212.606
A13: 玉米总需求（万吨） | B13: =(AD13/K13)^(1/19)*100-100 -> -100 | J13: TOTAL DEMAND | K13: 30855 | L13: 30387.81 | M13: 30545.286 | N13: 30933.839 | O13: 31114.972 | P13: 31261.372 | Q13: 31392.522 | R13: 31513.955 | S13: 31631.802 | T13: 31747.263 | U13: 31860.016 | V13: 31970.252
A14: 玉米人均消费量（千克/人） | B14: =(AD14/K14)^(1/19)*100-100 -> -100 | J14: PER CAPITA FOOD DEMAND | K14: 13.420627 | L14: 13.66655 | M14: 13.621324 | N14: 13.582632 | O14: 13.549074 | P14: 13.52084 | Q14: 13.497113 | R14: 13.476676 | S14: 13.459437 | T14: 13.444891 | U14: 13.432753 | V14: 13.42273
A15: 农村居民在家人均玉米消费量（千克/人） | B15: =(AD15/K15)^(1/19)*100-100 -> -100 | J15: SEED DEMAND | K15: 127 | L15: 124.5 | M15: 124.41515 | N15: 124.32464 | O15: 124.23455 | P15: 124.13538 | Q15: 124.03419 | R15: 123.93811 | S15: 123.84689 | T15: 123.76027 | U15: 123.67802 | V15: 123.59992
A16: 玉米饲料消费量（万吨） | B16: =(AD16/K16)^(1/19)*100-100 -> -100 | J16: FEED DEMAND | K16: 17200 | L16: 19500 | M16: 19543.819 | N16: 19550.304 | O16: 19582.434 | P16: 19626.189 | Q16: 19670.18 | R16: 19715.094 | S16: 19761.889 | T16: 19810.469 | U16: 19860.798 | V16: 19912.823
A17: 农村居民在外人均玉米消费量（千克/人） | B17: =(AD17/K17)^(1/19)*100-100 -> -100 | J17: PROCESSING DEMAND | K17: 7750 | L17: 7900 | M17: 7988.9642 | N17: 8077.3944 | O17: 8161.2548 | P17: 8241.2526 | Q17: 8319.5743 | R17: 8392.9707 | S17: 8462.5106 | T17: 8529.1703 | U17: 8592.0455 | V17: 8651.0312
A18: 城镇居民在家人均玉米消费量（千克/人） | B18: =(AD18/K18)^(1/19)*100-100 -> -100 | J18: WASTE DEMAND | K18: 1474.6 | L18: 1506.175 | M18: 1513.9621 | N18: 1521.7184 | O18: 1529.587 | P18: 1537.4219 | Q18: 1545.3299 | R18: 1553.4122 | S18: 1561.6862 | T18: 1570.1813 | U18: 1578.9078 | V18: 1587.8823
A19: 城镇居民在外人均玉米消费量（千克/人） | B19: =(AD19/K19)^(1/19)*100-100 -> -100 | J19: STOCK CHANGE | K19: 2413.4 | L19: -562.865 | M19: -537.48631 | N19: -243.10798 | O19: -177.16467 | P19: -153.58723 | Q19: -143.76379 | R19: -139.54798 | S19: -137.88 | T19: -137.43867 | U19: -137.60867 | V19: -138.09351
... A23: 玉米加工消费量（万吨） | B23: =(AD23/K23)^(1/19)*100-100 -> -100 | J23: CARBON EMISSION | K23: 5539.3519 | L23: 5334.497 | M23: 5312.1164 | N23: 5333.3655 | O23: 5314.6677 | P23: 5289.2843 | Q23: 5260.9182 | R23: 5230.6248 | S23: 5199.5047 | T23: 5167.699 | U23: 5135.1385 | V23: 5101.828
A24: 玉米损耗量（万吨） | B24: =(AD24/K24)^(1/19)*100-100 -> #DIV/0!
A29: 农村居民人均玉米消费量（千克/人） | B29: =(AD29/K29)^(1/19)*100-100 -> #DIV/0!
A30: 城镇居民人均玉米消费量（千克/人） | B30: =(AD30/K30)^(1/19)*100-100 -> #DIV/0!
A31: 农村居民在家玉米口粮总消费量（万吨） | B31: =(AD31/K31)^(1/19)*100-100 -> #DIV/0!
A32: 农村居民在外玉米口粮总消费量（万吨） | B32: =(AD32/K32)^(1/19)*100-100 -> #DIV/0!
A33: 城镇居民在家玉米口粮总消费量（万吨） | B33: =(AD33/K33)^(1/19)*100-100 -> #DIV/0!
A34: 城镇居民在外玉米口粮总消费量（万吨） | B34: =(AD34/K34)^(1/19)*100-100 -> #DIV/0!
B35: =(AD35/K35)^(1/19)*100-100 -> #DIV/0!

Sheet BARLX
B6: BASE | K6: BASE | L6: BASE | M6: BASE | N6: BASE | O6: BASE | P6: BASE | Q6: BASE | R6: BASE | S6: BASE | T6: BASE | U6: BASE | V6: BASE
B7: 2016-2035 | K7: 2024 | L7: 2025 | M7: 2026 | N7: 2027 | O7: 2028 | P7: 2029 | Q7: 2030 | R7: 2031 | S7: 2032 | T7: 2033 | U7: 2034 | V7: 2035
A8: 大豆种植面积（万公顷） | B8: =(AD8/K8)^(1/19)*100-100 -> -100 | J8: AREA | K8: 50 | L8: 56 | M8: 55.968776 | N8: 55.937178 | O8: 55.90516 | P8: 55.872708 | Q8: 55.840274 | R8: 55.809462 | S8: 55.78019 | T8: 55.752382 | U8: 55.725964 | V8: 55.700867
A9: 大豆单产（千克/公顷） | B9: =(AD9/K9)^(1/19)*100-100 -> -100 | J9: YIELD | K9: 4000 | L9: 4107.1429 | M9: 4103.4403 | N9: 4099.7739 | O9: 4096.2082 | P9: 4092.883 | Q9: 4089.717 | R9: 4086.4884 | S9: 4083.2569 | T9: 4080.1119 | U9: 4077.0907 | V9: 4074.2445
A10: 总供给 | B10: =(AD10/K10)^(1/19)*100-100 -> -100 | J10: TOTAL SUPPLY | K10: 1624 | L10: 1280 | M10: 1285.4475 | N10: 1290.0101 | O10: 1295.0205 | P10: 1300.1757 | Q10: 1305.2791 | R10: 1310.3008 | S10: 1315.3345 | T10: 1320.3343 | U10: 1325.279 | V10: 1330.1636
A11: 大豆产量（万吨） | B11: =(AD11/K11)^(1/19)*100-100 -> -100 | J11: PRODUCTION | K11: 200 | L11: 230 | M11: 229.66453 | N11: 229.32978 | O11: 228.99918 | P11: 228.68046 | Q11: 228.37092 | R11: 228.06472 | S11: 227.76485 | T11: 227.47596 | U11: 227.19981 | V11: 226.93895
A12: 大豆净进口 | B12: =(AD12/K12)^(1/19)*100-100 -> -100 | J12: NET IMPORT | K12: 1424 | L12: 1050 | M12: 1055.783 | N12: 1060.6803 | O12: 1066.0213 | P12: 1071.4953 | Q12: 1076.9082 | R12: 1082.2361 | S12: 1087.5696 | T12: 1092.8584 | U12: 1098.0792 | V12: 1103.2247
A13: 大豆总需求（万吨） | B13: =(AD13/K13)^(1/19)*100-100 -> -100 | J13: TOTAL DEMAND | K13: 1624 | L13: 1280 | M13: 1285.4475 | N13: 1290.0101 | O13: 1295.0205 | P13: 1300.1757 | Q13: 1305.2791 | R13: 1310.3008 | S13: 1315.3345 | T13: 1320.3343 | U13: 1325.279 | V13: 1330.1636
A14: 大豆人均消费量（千克/人） | B14: =(AD14/K14)^(1/19)*100-100 -> -100 | J14: PER CAPITA FOOD DEMAND | K14: 0.63424887 | L14: 0.27333101 | M14: 0.2722941 | N14: 0.27145029 | O14: 0.27074832 | P14: 0.27016413 | Q14: 0.26969559 | R14: 0.26932505 | S14: 0.26906813 | T14: 0.2688977 | U14: 0.26880477 | V14: 0.26877877
A15: 农村居民在家人均大豆消费量（千克/人） | B15: =(AD15/K15)^(1/19)*100-100 -> -100 | J15: SEED DEMAND | K15: 8.12 | L15: 6.4 | M15: 6.3964316 | N15: 6.3928204 | O15: 6.3891612 | P15: 6.3854523 | Q15: 6.3817456 | R15: 6.3782242 | S15: 6.3748789 | T15: 6.3717008 | U15: 6.3686816 | V15: 6.3658134
A16: 城镇居民在家人均大豆消费量（千克/人） | B16: =(AD16/K16)^(1/19)*100-100 -> -100 | J16: FEED DEMAND | K16: 430 | L16: 430 | M16: 430.82986 | N16: 430.80282 | O16: 431.3404 | P16: 432.14004 | Q16: 432.94865 | R16: 433.78072 | S16: 434.65344 | T16: 435.5647 | U16: 436.51365 | V16: 437.4991
A17: 农村居民大豆口粮总消费量（万吨） | B17: =(AD17/K17)^(1/19)*100-100 -> -100 | J17: PROCESSING DEMAND | K17: 1055.16 | L17: 789.6 | M17: 794.43029 | N17: 799.22415 | O17: 803.89889 | P17: 808.4558 | Q17: 812.95014 | R17: 817.34023 | S17: 821.67943 | T17: 825.94672 | U17: 830.12214 | V17: 834.20188
A18: 城镇居民大豆口粮总消费量（万吨） | B18: =(AD18/K18)^(1/19)*100-100 -> -100 | J18: WASTE DEMAND | K18: 81.2 | L18: 25.6 | M18: 25.562661 | N18: 25.525402 | O18: 25.488604 | P18: 25.453129 | Q18: 25.418676 | R18: 25.384595 | S18: 25.351218 | T18: 25.319063 | U18: 25.288326 | V18: 25.259292
A19: 大豆加工消费量（万吨） | B19: =(AD19/K19)^(1/19)*100-100 -> -100 | J19: STOCK CHANGE | K19: -39.8 | L19: -10 | M19: -9.9854145 | N19: -9.9708601 | O19: -9.956486 | P19: -9.9426286 | Q19: -9.9291703 | R19: -9.9158573 | S19: -9.9028194 | T19: -9.8902591 | U19: -9.8782525 | V19: -9.8669111
... A23: 大豆生产者价格（元/吨） | B23: =(AD23/K23)^(1/19)*100-100 -> -100 | J23: CARBON EMISSION | K23: 1.0067426 | L23: -8.8816557 | M23: -8.7333545 | N23: -8.6101242 | O23: -8.4735927 | P23: -8.3321664 | Q23: -8.1916857 | R23: -8.0534633 | S23: -7.9146815 | T23: -7.7764916 | U23: -7.6394508 | V23: -7.5036196
A24: 食物总需求 | B24: =(AD24/K24)^(1/19)*100-100 -> #DIV/0!
A25: 农村居民人均大豆消费量（千克/人） | B25: =(AD25/K25)^(1/19)*100-100 -> #DIV/0!
A26: 城镇居民人均大豆消费量（千克/人） | B26: =(AD26/K26)^(1/19)*100-100 -> #DIV/0!
A27: 农村居民在家大豆口粮总消费量（万吨） | B27: =(AD27/K27)^(1/19)*100-100 -> #DIV/0!
A28: 城镇居民在家大豆口粮总消费量（万吨） | B28: =(AD28/K28)^(1/19)*100-100 -> #DIV/0!

Sheet POTAX
B6: BASE | K6: BASE | L6: BASE | M6: BASE | N6: BASE | O6: BASE | P6: BASE | Q6: BASE | R6: BASE | S6: BASE | T6: BASE | U6: BASE | V6: BASE
B7: 2016-2035 | K7: 2024 | L7: 2025 | M7: 2026 | N7: 2027 | O7: 2028 | P7: 2029 | Q7: 2030 | R7: 2031 | S7: 2032 | T7: 2033 | U7: 2034 | V7: 2035
I8: 1 | J8: AREA | K8: 470 | L8: 453.18 | M8: 453.28764 | N8: 453.39361 | O8: 453.49483 | P8: 453.60374 | Q8: 453.70651 | R8: 453.80415 | S8: 453.89689 | T8: 453.985 | U8: 454.06869 | V8: 454.14819
I9: 2 | J9: YIELD | K9: 20212.766 | L9: 21733.836 | M9: 21761.639 | N9: 21789.748 | O9: 21818.572 | P9: 21848.994 | Q9: 21880.296 | R9: 21912.15 | S9: 21944.834 | T9: 21978.795 | U9: 22014.201 | V9: 22051.302
I10: 3 | J10: TOTAL SUPPLY | K10: 9500 | L10: 9849.34 | M10: 9864.2819 | N10: 9879.3324 | O10: 9894.6094 | P10: 9910.7854 | Q10: 9927.2329 | R10: 9943.8243 | S10: 9960.6922 | T10: 9978.0433 | U10: 9995.9595 | V10: 10014.559
I11: 4 | J11: PRODUCTION | K11: 9500 | L11: 9849.34 | M11: 9864.2819 | N11: 9879.3324 | O11: 9894.6094 | P11: 9910.7854 | Q11: 9927.2329 | R11: 9943.8243 | S11: 9960.6922 | T11: 9978.0433 | U11: 9995.9595 | V11: 10014.559
I12: 5 | J12: TOTAL DEMAND | K12: 9500 | L12: 9864.04 | M12: 9864.2819 | N12: 9879.3324 | O12: 9894.6094 | P12: 9910.7854 | Q12: 9927.2329 | R12: 9943.8243 | S12: 9960.6922 | T12: 9978.0433 | U12: 9995.9595 | V12: 10014.559
I13: 6 | J13: PER CAPITA FOOD DEMAND | K13: 43.186866 | L13: 44.785286 | M13: 44.719125 | N13: 44.677169 | O13: 44.651463 | P13: 44.637374 | Q13: 44.637146 | R13: 44.646395 | S13: 44.668809 | T13: 44.700224 | U13: 44.739523 | V13: 44.785438
I14: 7 | J14: SEED DEMAND | K14: 855.27 | L14: 884.79 | M14: 885.00016 | N14: 885.20706 | O14: 885.40467 | P14: 885.6173 | Q14: 885.81797 | R14: 886.00859 | S14: 886.18966 | T14: 886.36168 | U14: 886.52508 | V14: 886.68031
I15: 8 | J15: FEED DEMAND | K15: 570.18 | L15: 589.86 | M15: 590.99837 | N15: 590.96129 | O15: 591.69871 | P15: 592.79563 | Q15: 593.90486 | R15: 595.04626 | S15: 596.24344 | T15: 597.49347 | U15: 598.79521 | V15: 600.14702
I16: 9 | J16: PROCESSING DEMAND | K16: 950.3 | L16: 983.1 | M16: 1008.084 | N16: 1033.4997 | O16: 1058.8434 | P16: 1084.1608 | Q16: 1109.7555 | R16: 1135.2002 | S16: 1160.623 | T16: 1186.1465 | U16: 1211.6351 | V16: 1237.0603
I17: 10 | J17: WASTE DEMAND | K17: 987.33 | L17: 1015.43 | M17: 1016.9705 | N17: 1018.5221 | O17: 1020.0971 | P17: 1021.7648 | Q17: 1023.4605 | R17: 1025.171 | S17: 1026.91 | T17: 1028.6988 | U17: 1030.5459 | V17: 1032.4635
I18: 11 | J18: NET EXPORT | K18: 55 | L18: 99.02 | M18: 87.360368 | N18: 90.951929 | O18: 94.754514 | P18: 100.18437 | Q18: 106.19735 | R18: 113.67746 | S18: 118.64154 | T18: 124.9217 | U18: 132.7869 | V18: 142.30729
I19: 12 | J19: DOMESTIC DEMAND | K19: 9445 | L19: 9765.02 | M19: 9776.9215 | N19: 9788.3805 | O19: 9799.8549 | P19: 9810.601 | Q19: 9821.0355 | R19: 9830.1469 | S19: 9842.0506 | T19: 9853.1216 | U19: 9863.1726 | V19: 9872.2518
... I21: 14 | J21: TOTAL FOOD DEMAND BY ALL HOUSEHOLD | K21: 6081.92 | L21: 6291.84 | M21: 6275.8686 | N21: 6260.1904 | O21: 6243.811 | P21: 6226.2625 | Q21: 6208.0967 | R21: 6188.7208 | S21: 6172.0845 | T21: 6154.4212 | U21: 6135.6713 | V21: 6115.9007

Sheet SOYSX
W2: =W9/W8 -> #DIV/0!
K3: =K11/15 -> 137.66667 | L3: =L11/15 -> 139.4 | M3: =M11/15 -> 147.19057 | N3: =N11/15 -> 155.42001 | O3: =O11/15 -> 164.11439 | P3: =P11/15 -> 173.31268 | Q3: =Q11/15 -> 183.03352 | R3: =R11/15 -> 189.58584 | ... W3: =W11/15 -> 0
L5: =L11/L10 -> 0.15760673 | N5: =N9/N8 -> 2.0545177 | S5: =S9/S8 -> 2.1513258 | X5: =X9/X8 -> #DIV/0!
B6: BASE | K6: BASE | L6: BASE | M6: BASE | N6: BASE | O6: BASE | P6: BASE | Q6: BASE | R6: BASE | S6: BASE | T6: BASE | U6: BASE | V6: BASE
B7: 2016-2035 | K7: 2024 | L7: 2025 | M7: 2026 | N7: 2027 | O7: 2028 | P7: 2029 | Q7: 2030 | R7: 2031 | S7: 2032 | T7: 2033 | U7: 2034 | V7: 2035
A8: 总供给 | B8: =(AD8/K8)^(1/19)*100-100 -> -100 | J8: AREA | K8: 1033.333 | L8: 1026 | M8: 1045.4271 | N8: 1065.2319 | O8: 1085.4085 | P8: 1105.9983 | Q8: 1126.9788 | R8: 1148.3587 | S8: 1170.1458 | T8: 1192.3478 | U8: 1214.9724 | V8: 1238.0278
A9: 大豆产量（万吨） | B9: =(AD9/K9)^(1/19)*100-100 -> -100 | J9: YIELD | K9: 1998.3877 | L9: 2038.0117 | M9: 2111.9202 | N9: 2188.5377 | O9: 2268.0086 | P9: 2350.5372 | Q9: 2436.162 | R9: 2476.3931 | S9: 2517.3649 | T9: 2559.1442 | U9: 2601.7687 | V9: 2645.2872
A10: 大豆种植面积（万公顷） | B10: =(AD10/K10)^(1/19)*100-100 -> -100 | J10: TOTAL SUPPLY | K10: 12562 | L10: 13267.2 | M10: 12895.576 | N10: 12799.238 | O10: 12768.403 | P10: 12774.58 | Q10: 12795.354 | R10: 12818.416 | S10: 12851.508 | T10: 12891.173 | U10: 12935.858 | V10: 12984.515
A11: 大豆单产（千克/公顷） | B11: =(AD11/K11)^(1/19)*100-100 -> -100 | J11: PRODUCTION | K11: 2065 | L11: 2091 | M11: 2207.8585 | N11: 2331.3001 | O11: 2461.7158 | P11: 2599.6902 | Q11: 2745.5028 | R11: 2843.7876 | S11: 2945.6841 | T11: 3051.3899 | U11: 3161.0772 | V11: 3274.9391
A12: 大豆净进口 | B12: =(AD12/K12)^(1/19)*100-100 -> -100 | J12: NET IMPORT | K12: 10497 | L12: 11176.2 | M12: 10687.717 | N12: 10467.938 | O12: 10306.687 | P12: 10174.889 | Q12: 10049.852 | R12: 9974.6287 | S12: 9905.8241 | T12: 9839.7829 | U12: 9774.7808 | V12: 9709.5755
A13: 大豆总需求（万吨） | B13: =(AD13/K13)^(1/19)*100-100 -> -100 | J13: TOTAL DEMAND | K13: 12562 | L13: 13267.2 | M13: 12895.576 | N13: 12799.238 | O13: 12768.403 | P13: 12774.58 | Q13: 12795.354 | R13: 12818.416 | S13: 12851.508 | T13: 12891.173 | U13: 12935.858 | V13: 12984.515
A14: 大豆人均消费量（千克/人） | B14: =(AD14/K14)^(1/19)*100-100 -> -100 | J14: PER CAPITA FOOD DEMAND | K14: 11.893942 | L14: 12.100592 | M14: 12.163543 | N14: 12.231232 | O14: 12.299348 | P14: 12.367241 | Q14: 12.435914 | R14: 12.503463 | S14: 12.573161 | T14: 12.642963 | U14: 12.712614 | V14: 12.781885
A15: 农村居民在家人均大豆消费量（千克/人） | B15: =(AD15/K15)^(1/19)*100-100 -> -100 | J15: SEED DEMAND | K15: 83.699973 | L15: 83.106 | M15: 84.679593 | N15: 86.283781 | O15: 87.918089 | P15: 89.585865 | Q15: 91.285279 | R15: 93.017057 | S15: 94.781812 | T15: 96.58017 | U15: 98.412767 | V15: 100.28025
A16: 大豆库存变化(万吨） | B16: =(AD16/K16)^(1/19)*100-100 -> -100 | J16: CRUSH DEMAND | K16: 10240 | L16: 10650 | M16: 10423.108 | N16: 10418.995 | O16: 10447.838 | P16: 10492.532 | Q16: 10537.434 | R16: 10582.903 | S16: 10629.463 | T16: 10677.067 | U16: 10725.696 | V16: 10775.326
A17: 城镇居民在家人均大豆消费量（千克/人） | B17: =(AD17/K17)^(1/19)*100-100 -> -100 | J17: WASTE DEMAND | K17: 125.68 | L17: 132.743 | M17: 140.16153 | N17: 147.99798 | O17: 156.27716 | P17: 165.03619 | Q17: 174.29282 | R17: 180.53223 | S17: 187.00093 | T17: 193.71145 | U17: 200.67474 | V17: 207.90303
A18: 农村居民大豆口粮总消费量（万吨） | B18: =(AD18/K18)^(1/19)*100-100 -> -100 | J18: STOCK CHANGE | K18: 437.62003 | L18: 701.351 | M18: 540.59931 | N18: 432.11398 | O18: 356.497 | P18: 302.3758 | Q18: 262.76625 | R18: 228.77973 | S18: 202.97355 | T18: 183.1046 | U18: 167.64006 | V18: 155.51107
A19: 城镇居民大豆口粮总消费量（万吨） | B19: =(AD19/K19)^(1/19)*100-100 -> -100 | J19: DOMESTIC DEMAND | K19: 12124.38 | L19: 12565.849 | M19: 12354.977 | N19: 12367.124 | O19: 12411.906 | P19: 12472.204 | Q19: 12532.588 | R19: 12589.637 | S19: 12648.535 | T19: 12708.068 | U19: 12768.218 | V19: 12829.004
... A22: 大豆消费者价格（元/吨） | B22: =(AD22/K22)^(1/19)*100-100 -> -100 | J22: CARBON EMISSION | K22: 560.81394 | L22: 690.2009 | M22: 591.3684 | N22: 550.51406 | O22: 523.67204 | P22: 504.43187 | Q22: 488.30044 | R22: 482.29562 | S22: 477.9212 | T22: 474.53341 | U22: 471.83269 | V22: 469.61437
A23: 大豆生产者价格（元/吨） | B23: =(AD23/K23)^(1/19)*100-100 -> #DIV/0!
A24: 食物总需求 | B24: =(AD24/K24)^(1/19)*100-100 -> #DIV/0!
A25: 农村居民人均大豆消费量（千克/人） | B25: =(AD25/K25)^(1/19)*100-100 -> #DIV/0!
A26: 城镇居民人均大豆消费量（千克/人） | B26: =(AD26/K26)^(1/19)*100-100 -> #DIV/0!
A27: 农村居民在家大豆口粮总消费量（万吨） | B27: =(AD27/K27)^(1/19)*100-100 -> #DIV/0!
A28: 城镇居民在家大豆口粮总消费量（万吨） | B28: =(AD28/K28)^(1/19)*100-100 -> #DIV/0!

Sheet SOYOX
B6: BASE | K6: BASE | L6: BASE | M6: BASE | N6: BASE | O6: BASE | P6: BASE | Q6: BASE | R6: BASE | S6: BASE | T6: BASE | U6: BASE | V6: BASE
B7: 2016-2035 | K7: 2024 | L7: 2025 | M7: 2026 | N7: 2027 | O7: 2028 | P7: 2029 | Q7: 2030 | R7: 2031 | S7: 2032 | T7: 2033 | U7: 2034 | V7: 2035
J8: TOTAL SUPPLY | K8: 1817 | L8: 1871 | M8: 1876.9205 | N8: 1883.3666 | O8: 1889.0787 | P8: 1893.9642 | Q8: 1898.2203 | R8: 1901.6318 | S8: 1905.6286 | T8: 1908.9666 | U8: 1911.6465 | V8: 1913.6889
J9: PRODUCTION | K9: 1790 | L9: 1871 | M9: 1876.9205 | N9: 1883.3666 | O9: 1889.0787 | P9: 1893.9642 | Q9: 1898.2203 | R9: 1901.6318 | S9: 1905.6286 | T9: 1908.9666 | U9: 1911.6465 | V9: 1913.6889
J10: NET IMPORT | K10: 27
J11: TOTAL DEMAND | K11: 1817 | L11: 1871 | M11: 1876.9205 | N11: 1883.3666 | O11: 1889.0787 | P11: 1893.9642 | Q11: 1898.2203 | R11: 1901.6318 | S11: 1905.6286 | T11: 1908.9666 | U11: 1911.6465 | V11: 1913.6889
J12: PER CAPITA FOOD DEMAND | K12: 12.767347 | L12: 13.159322 | M12: 13.220425 | N12: 13.287104 | O12: 13.355144 | P12: 13.423584 | Q12: 13.493397 | R12: 13.563058 | S12: 13.63537 | T12: 13.708365 | U12: 13.781886 | V12: 13.855584
J13: STOCK CHANGE | K13: 19 | L13: 0.69 | M13: 0.6921834 | N13: 0.69456064 | O13: 0.69666718 | P13: 0.69846888 | Q13: 0.7000385 | R13: 0.7012966 | S13: 0.70277057 | T13: 0.70400159 | U13: 0.70498991 | V13: 0.70574311
J14: NET EXPORT | L14: 21.57 | M14: 20.877817 | N14: 20.875439 | O14: 20.873333 | P14: 20.871531 | Q14: 20.869961 | R14: 20.868703 | S14: 20.867229 | T14: 20.865998 | U14: 20.86501 | V14: 20.864257
J15: DOMESTIC DEMAND | K15: 1798 | L15: 1848.74 | M15: 1855.3505 | N15: 1861.7966 | O15: 1867.5087 | P15: 1872.3942 | Q15: 1876.6503 | R15: 1880.0618 | S15: 1884.0586 | T15: 1887.3966 | U15: 1890.0765 | V15: 1892.1189
J16: energy | K16: 309.2883 | L16: 318.78387 | M16: 320.26408 | N16: 321.87938 | O16: 323.52764 | P16: 325.1856 | Q16: 326.87682 | R16: 328.56436 | S16: 330.31609 | T16: 332.0844 | U16: 333.86545 | V16: 335.65077
J17: TOTAL FOOD DEMAND BY ALL HOUSEHOLD | K17: 1798 | L17: 1848.74 | M17: 1855.3505 | N17: 1861.7966 | O17: 1867.5087 | P17: 1872.3942 | Q17: 1876.6503 | R17: 1880.0618 | S17: 1884.0586 | T17: 1887.3966 | U17: 1890.0765 | V17: 1892.1189

Sheet SOYMX
B6: BASE | K6: BASE | L6: BASE | M6: BASE | N6: BASE | O6: BASE | P6: BASE | Q6: BASE | R6: BASE | S6: BASE | T6: BASE | U6: BASE | V6: BASE
B7: 2016-2035 | K7: 2024 | L7: 2025 | M7: 2026 | N7: 2027 | O7: 2028 | P7: 2029 | Q7: 2030 | R7: 2031 | S7: 2032 | T7: 2033 | U7: 2034 | V7: 2035
J8: TOTAL SUPPLY | K8: 7729.4 | L8: 8100 | M8: 8045.9737 | N8: 8042.7683 | O8: 8065.2495 | P8: 8100.0851 | Q8: 8135.0825 | R8: 8170.5225 | S8: 8206.8131 | T8: 8243.9166 | U8: 8281.8197 | V8: 8320.5023
J9: PRODUCTION | K9: 7729.4 | L9: 8100 | M9: 7927.4339 | N9: 7924.3062 | O9: 7946.2432 | P9: 7980.2357 | Q9: 8014.386 | R9: 8048.9683 | S9: 8084.3805 | T9: 8120.586 | U9: 8157.5717 | V9: 8195.3181
J10: NET IMPORT | M10: 118.53972 | N10: 118.46214 | O10: 119.00626 | P10: 119.8494 | Q10: 120.69646 | R10: 121.55423 | S10: 122.43258 | T10: 123.33061 | U10: 124.24799 | V10: 125.18424
J11: TOTAL DEMAND | K11: 7729.4 | L11: 8100 | M11: 8045.9737 | N11: 8042.7683 | O11: 8065.2495 | P11: 8100.0851 | Q11: 8135.0825 | R11: 8170.5225 | S11: 8206.8131 | T11: 8243.9166 | U11: 8281.8197 | V11: 8320.5023
J12: FEED DEMAND | K12: 7540 | L12: 7821 | M12: 7849.3439 | N12: 7846.2162 | O12: 7868.1532 | P12: 7902.1457 | Q12: 7936.296 | R12: 7970.8783 | S12: 8006.2905 | T12: 8042.496 | U12: 8079.4817 | V12: 8117.2281
